[2023-07-10 22:24:13,363][apps.utils.exception.CustomExceptionHandler():64] [ERROR] Traceback (most recent call last):
  File "/usr/local/lib/python3.11/site-packages/django/db/backends/utils.py", line 84, in _execute
    return self.cursor.execute(sql, params)
           ^^^^^^^^^^^^^^^^^^^^^^^^^^^^^^^^
  File "/usr/local/lib/python3.11/site-packages/django/db/backends/mysql/base.py", line 73, in execute
    return self.cursor.execute(query, args)
           ^^^^^^^^^^^^^^^^^^^^^^^^^^^^^^^^
  File "/usr/local/lib/python3.11/site-packages/MySQLdb/cursors.py", line 206, in execute
    res = self._query(query)
          ^^^^^^^^^^^^^^^^^^
  File "/usr/local/lib/python3.11/site-packages/MySQLdb/cursors.py", line 319, in _query
    db.query(q)
  File "/usr/local/lib/python3.11/site-packages/MySQLdb/connections.py", line 254, in query
    _mysql.connection.query(self, query)
MySQLdb.IntegrityError: (1062, "Duplicate entry 'test' for key 'username'")

The above exception was the direct cause of the following exception:

Traceback (most recent call last):
  File "/usr/local/lib/python3.11/site-packages/rest_framework/views.py", line 506, in dispatch
    response = handler(request, *args, **kwargs)
               ^^^^^^^^^^^^^^^^^^^^^^^^^^^^^^^^^
  File "/Users/mac/Desktop/work/server/apps/utils/viewset.py", line 75, in create
    self.perform_create(serializer)
  File "/usr/local/lib/python3.11/site-packages/rest_framework/mixins.py", line 24, in perform_create
    serializer.save()
  File "/Users/mac/Desktop/work/server/apps/admin/views/member.py", line 110, in save
    data = super().save(**kwargs)
           ^^^^^^^^^^^^^^^^^^^^^^
  File "/Users/mac/Desktop/work/server/apps/utils/serializers.py", line 62, in save
    return super().save(**kwargs)
           ^^^^^^^^^^^^^^^^^^^^^^
  File "/usr/local/lib/python3.11/site-packages/rest_framework/serializers.py", line 212, in save
    self.instance = self.create(validated_data)
                    ^^^^^^^^^^^^^^^^^^^^^^^^^^^
  File "/Users/mac/Desktop/work/server/apps/utils/serializers.py", line 79, in create
    return super().create(validated_data)
           ^^^^^^^^^^^^^^^^^^^^^^^^^^^^^^
  File "/usr/local/lib/python3.11/site-packages/rest_framework/serializers.py", line 962, in create
    instance = ModelClass._default_manager.create(**validated_data)
               ^^^^^^^^^^^^^^^^^^^^^^^^^^^^^^^^^^^^^^^^^^^^^^^^^^^^
  File "/usr/local/lib/python3.11/site-packages/django/db/models/manager.py", line 85, in manager_method
    return getattr(self.get_queryset(), name)(*args, **kwargs)
           ^^^^^^^^^^^^^^^^^^^^^^^^^^^^^^^^^^^^^^^^^^^^^^^^^^^
  File "/usr/local/lib/python3.11/site-packages/django/db/models/query.py", line 453, in create
    obj.save(force_insert=True, using=self.db)
  File "/usr/local/lib/python3.11/site-packages/django/contrib/auth/base_user.py", line 67, in save
    super().save(*args, **kwargs)
  File "/usr/local/lib/python3.11/site-packages/django/db/models/base.py", line 739, in save
    self.save_base(using=using, force_insert=force_insert,
  File "/usr/local/lib/python3.11/site-packages/django/db/models/base.py", line 776, in save_base
    updated = self._save_table(
              ^^^^^^^^^^^^^^^^^
  File "/usr/local/lib/python3.11/site-packages/django/db/models/base.py", line 881, in _save_table
    results = self._do_insert(cls._base_manager, using, fields, returning_fields, raw)
              ^^^^^^^^^^^^^^^^^^^^^^^^^^^^^^^^^^^^^^^^^^^^^^^^^^^^^^^^^^^^^^^^^^^^^^^^
  File "/usr/local/lib/python3.11/site-packages/django/db/models/base.py", line 919, in _do_insert
    return manager._insert(
           ^^^^^^^^^^^^^^^^
  File "/usr/local/lib/python3.11/site-packages/django/db/models/manager.py", line 85, in manager_method
    return getattr(self.get_queryset(), name)(*args, **kwargs)
           ^^^^^^^^^^^^^^^^^^^^^^^^^^^^^^^^^^^^^^^^^^^^^^^^^^^
  File "/usr/local/lib/python3.11/site-packages/django/db/models/query.py", line 1270, in _insert
    return query.get_compiler(using=using).execute_sql(returning_fields)
           ^^^^^^^^^^^^^^^^^^^^^^^^^^^^^^^^^^^^^^^^^^^^^^^^^^^^^^^^^^^^^
  File "/usr/local/lib/python3.11/site-packages/django/db/models/sql/compiler.py", line 1416, in execute_sql
    cursor.execute(sql, params)
  File "/usr/local/lib/python3.11/site-packages/django/db/backends/utils.py", line 98, in execute
    return super().execute(sql, params)
           ^^^^^^^^^^^^^^^^^^^^^^^^^^^^
  File "/usr/local/lib/python3.11/site-packages/django/db/backends/utils.py", line 66, in execute
    return self._execute_with_wrappers(sql, params, many=False, executor=self._execute)
           ^^^^^^^^^^^^^^^^^^^^^^^^^^^^^^^^^^^^^^^^^^^^^^^^^^^^^^^^^^^^^^^^^^^^^^^^^^^^
  File "/usr/local/lib/python3.11/site-packages/django/db/backends/utils.py", line 75, in _execute_with_wrappers
    return executor(sql, params, many, context)
           ^^^^^^^^^^^^^^^^^^^^^^^^^^^^^^^^^^^^
  File "/usr/local/lib/python3.11/site-packages/django/db/backends/utils.py", line 79, in _execute
    with self.db.wrap_database_errors:
  File "/usr/local/lib/python3.11/site-packages/django/db/utils.py", line 90, in __exit__
    raise dj_exc_value.with_traceback(traceback) from exc_value
  File "/usr/local/lib/python3.11/site-packages/django/db/backends/utils.py", line 84, in _execute
    return self.cursor.execute(sql, params)
           ^^^^^^^^^^^^^^^^^^^^^^^^^^^^^^^^
  File "/usr/local/lib/python3.11/site-packages/django/db/backends/mysql/base.py", line 73, in execute
    return self.cursor.execute(query, args)
           ^^^^^^^^^^^^^^^^^^^^^^^^^^^^^^^^
  File "/usr/local/lib/python3.11/site-packages/MySQLdb/cursors.py", line 206, in execute
    res = self._query(query)
          ^^^^^^^^^^^^^^^^^^
  File "/usr/local/lib/python3.11/site-packages/MySQLdb/cursors.py", line 319, in _query
    db.query(q)
  File "/usr/local/lib/python3.11/site-packages/MySQLdb/connections.py", line 254, in query
    _mysql.connection.query(self, query)
django.db.utils.IntegrityError: (1062, "Duplicate entry 'test' for key 'username'")
Traceback (most recent call last):
  File "/usr/local/lib/python3.11/site-packages/django/db/backends/utils.py", line 84, in _execute
    return self.cursor.execute(sql, params)
           ^^^^^^^^^^^^^^^^^^^^^^^^^^^^^^^^
  File "/usr/local/lib/python3.11/site-packages/django/db/backends/mysql/base.py", line 73, in execute
    return self.cursor.execute(query, args)
           ^^^^^^^^^^^^^^^^^^^^^^^^^^^^^^^^
  File "/usr/local/lib/python3.11/site-packages/MySQLdb/cursors.py", line 206, in execute
    res = self._query(query)
          ^^^^^^^^^^^^^^^^^^
  File "/usr/local/lib/python3.11/site-packages/MySQLdb/cursors.py", line 319, in _query
    db.query(q)
  File "/usr/local/lib/python3.11/site-packages/MySQLdb/connections.py", line 254, in query
    _mysql.connection.query(self, query)
MySQLdb.IntegrityError: (1062, "Duplicate entry 'test' for key 'username'")

The above exception was the direct cause of the following exception:

Traceback (most recent call last):
  File "/usr/local/lib/python3.11/site-packages/rest_framework/views.py", line 506, in dispatch
    response = handler(request, *args, **kwargs)
               ^^^^^^^^^^^^^^^^^^^^^^^^^^^^^^^^^
  File "/Users/mac/Desktop/work/server/apps/utils/viewset.py", line 75, in create
    self.perform_create(serializer)
  File "/usr/local/lib/python3.11/site-packages/rest_framework/mixins.py", line 24, in perform_create
    serializer.save()
  File "/Users/mac/Desktop/work/server/apps/admin/views/member.py", line 110, in save
    data = super().save(**kwargs)
           ^^^^^^^^^^^^^^^^^^^^^^
  File "/Users/mac/Desktop/work/server/apps/utils/serializers.py", line 62, in save
    return super().save(**kwargs)
           ^^^^^^^^^^^^^^^^^^^^^^
  File "/usr/local/lib/python3.11/site-packages/rest_framework/serializers.py", line 212, in save
    self.instance = self.create(validated_data)
                    ^^^^^^^^^^^^^^^^^^^^^^^^^^^
  File "/Users/mac/Desktop/work/server/apps/utils/serializers.py", line 79, in create
    return super().create(validated_data)
           ^^^^^^^^^^^^^^^^^^^^^^^^^^^^^^
  File "/usr/local/lib/python3.11/site-packages/rest_framework/serializers.py", line 962, in create
    instance = ModelClass._default_manager.create(**validated_data)
               ^^^^^^^^^^^^^^^^^^^^^^^^^^^^^^^^^^^^^^^^^^^^^^^^^^^^
  File "/usr/local/lib/python3.11/site-packages/django/db/models/manager.py", line 85, in manager_method
    return getattr(self.get_queryset(), name)(*args, **kwargs)
           ^^^^^^^^^^^^^^^^^^^^^^^^^^^^^^^^^^^^^^^^^^^^^^^^^^^
  File "/usr/local/lib/python3.11/site-packages/django/db/models/query.py", line 453, in create
    obj.save(force_insert=True, using=self.db)
  File "/usr/local/lib/python3.11/site-packages/django/contrib/auth/base_user.py", line 67, in save
    super().save(*args, **kwargs)
  File "/usr/local/lib/python3.11/site-packages/django/db/models/base.py", line 739, in save
    self.save_base(using=using, force_insert=force_insert,
  File "/usr/local/lib/python3.11/site-packages/django/db/models/base.py", line 776, in save_base
    updated = self._save_table(
              ^^^^^^^^^^^^^^^^^
  File "/usr/local/lib/python3.11/site-packages/django/db/models/base.py", line 881, in _save_table
    results = self._do_insert(cls._base_manager, using, fields, returning_fields, raw)
              ^^^^^^^^^^^^^^^^^^^^^^^^^^^^^^^^^^^^^^^^^^^^^^^^^^^^^^^^^^^^^^^^^^^^^^^^
  File "/usr/local/lib/python3.11/site-packages/django/db/models/base.py", line 919, in _do_insert
    return manager._insert(
           ^^^^^^^^^^^^^^^^
  File "/usr/local/lib/python3.11/site-packages/django/db/models/manager.py", line 85, in manager_method
    return getattr(self.get_queryset(), name)(*args, **kwargs)
           ^^^^^^^^^^^^^^^^^^^^^^^^^^^^^^^^^^^^^^^^^^^^^^^^^^^
  File "/usr/local/lib/python3.11/site-packages/django/db/models/query.py", line 1270, in _insert
    return query.get_compiler(using=using).execute_sql(returning_fields)
           ^^^^^^^^^^^^^^^^^^^^^^^^^^^^^^^^^^^^^^^^^^^^^^^^^^^^^^^^^^^^^
  File "/usr/local/lib/python3.11/site-packages/django/db/models/sql/compiler.py", line 1416, in execute_sql
    cursor.execute(sql, params)
  File "/usr/local/lib/python3.11/site-packages/django/db/backends/utils.py", line 98, in execute
    return super().execute(sql, params)
           ^^^^^^^^^^^^^^^^^^^^^^^^^^^^
  File "/usr/local/lib/python3.11/site-packages/django/db/backends/utils.py", line 66, in execute
    return self._execute_with_wrappers(sql, params, many=False, executor=self._execute)
           ^^^^^^^^^^^^^^^^^^^^^^^^^^^^^^^^^^^^^^^^^^^^^^^^^^^^^^^^^^^^^^^^^^^^^^^^^^^^
  File "/usr/local/lib/python3.11/site-packages/django/db/backends/utils.py", line 75, in _execute_with_wrappers
    return executor(sql, params, many, context)
           ^^^^^^^^^^^^^^^^^^^^^^^^^^^^^^^^^^^^
  File "/usr/local/lib/python3.11/site-packages/django/db/backends/utils.py", line 79, in _execute
    with self.db.wrap_database_errors:
  File "/usr/local/lib/python3.11/site-packages/django/db/utils.py", line 90, in __exit__
    raise dj_exc_value.with_traceback(traceback) from exc_value
  File "/usr/local/lib/python3.11/site-packages/django/db/backends/utils.py", line 84, in _execute
    return self.cursor.execute(sql, params)
           ^^^^^^^^^^^^^^^^^^^^^^^^^^^^^^^^
  File "/usr/local/lib/python3.11/site-packages/django/db/backends/mysql/base.py", line 73, in execute
    return self.cursor.execute(query, args)
           ^^^^^^^^^^^^^^^^^^^^^^^^^^^^^^^^
  File "/usr/local/lib/python3.11/site-packages/MySQLdb/cursors.py", line 206, in execute
    res = self._query(query)
          ^^^^^^^^^^^^^^^^^^
  File "/usr/local/lib/python3.11/site-packages/MySQLdb/cursors.py", line 319, in _query
    db.query(q)
  File "/usr/local/lib/python3.11/site-packages/MySQLdb/connections.py", line 254, in query
    _mysql.connection.query(self, query)
django.db.utils.IntegrityError: (1062, "Duplicate entry 'test' for key 'username'")
[2023-08-02 20:48:37,762][apps.utils.exception.CustomExceptionHandler():64] [ERROR] Traceback (most recent call last):
  File "/usr/local/lib/python3.11/site-packages/rest_framework/views.py", line 506, in dispatch
    response = handler(request, *args, **kwargs)
               ^^^^^^^^^^^^^^^^^^^^^^^^^^^^^^^^^
  File "/usr/local/lib/python3.11/site-packages/drf_yasg/views.py", line 94, in get
    schema = generator.get_schema(request, self.public)
             ^^^^^^^^^^^^^^^^^^^^^^^^^^^^^^^^^^^^^^^^^^
  File "/Users/mac/Desktop/work/server/apps/utils/swagger.py", line 39, in get_schema
    swagger = super().get_schema(request, public)
              ^^^^^^^^^^^^^^^^^^^^^^^^^^^^^^^^^^^
  File "/usr/local/lib/python3.11/site-packages/drf_yasg/generators.py", line 248, in get_schema
    paths, prefix = self.get_paths(endpoints, components, request, public)
                    ^^^^^^^^^^^^^^^^^^^^^^^^^^^^^^^^^^^^^^^^^^^^^^^^^^^^^^
  File "/usr/local/lib/python3.11/site-packages/drf_yasg/generators.py", line 406, in get_paths
    operation = self.get_operation(view, path, prefix, method, components, request)
                ^^^^^^^^^^^^^^^^^^^^^^^^^^^^^^^^^^^^^^^^^^^^^^^^^^^^^^^^^^^^^^^^^^^
  File "/usr/local/lib/python3.11/site-packages/drf_yasg/generators.py", line 448, in get_operation
    operation = view_inspector.get_operation(operation_keys)
                ^^^^^^^^^^^^^^^^^^^^^^^^^^^^^^^^^^^^^^^^^^^^
  File "/usr/local/lib/python3.11/site-packages/drf_yasg/inspectors/view.py", line 45, in get_operation
    responses = self.get_responses()
                ^^^^^^^^^^^^^^^^^^^^
  File "/usr/local/lib/python3.11/site-packages/drf_yasg/inspectors/view.py", line 180, in get_responses
    response_serializers = self.get_response_serializers()
                           ^^^^^^^^^^^^^^^^^^^^^^^^^^^^^^^
  File "/usr/local/lib/python3.11/site-packages/drf_yasg/inspectors/view.py", line 235, in get_response_serializers
    responses = self.get_default_responses()
                ^^^^^^^^^^^^^^^^^^^^^^^^^^^^
  File "/usr/local/lib/python3.11/site-packages/drf_yasg/inspectors/view.py", line 211, in get_default_responses
    default_schema = self.serializer_to_schema(default_schema) or ''
                     ^^^^^^^^^^^^^^^^^^^^^^^^^^^^^^^^^^^^^^^^^
  File "/usr/local/lib/python3.11/site-packages/drf_yasg/inspectors/base.py", line 438, in serializer_to_schema
    return self.probe_inspectors(
           ^^^^^^^^^^^^^^^^^^^^^^
  File "/usr/local/lib/python3.11/site-packages/drf_yasg/inspectors/base.py", line 110, in probe_inspectors
    result = method(obj, **kwargs)
             ^^^^^^^^^^^^^^^^^^^^^
  File "/usr/local/lib/python3.11/site-packages/drf_yasg/inspectors/field.py", line 38, in get_schema
    return self.probe_field_inspectors(serializer, openapi.Schema, self.use_definitions)
           ^^^^^^^^^^^^^^^^^^^^^^^^^^^^^^^^^^^^^^^^^^^^^^^^^^^^^^^^^^^^^^^^^^^^^^^^^^^^^
  File "/usr/local/lib/python3.11/site-packages/drf_yasg/inspectors/base.py", line 228, in probe_field_inspectors
    return self.probe_inspectors(
           ^^^^^^^^^^^^^^^^^^^^^^
  File "/usr/local/lib/python3.11/site-packages/drf_yasg/inspectors/base.py", line 110, in probe_inspectors
    result = method(obj, **kwargs)
             ^^^^^^^^^^^^^^^^^^^^^
  File "/usr/local/lib/python3.11/site-packages/drf_yasg/inspectors/field.py", line 129, in field_to_swagger_object
    actual_schema = definitions.setdefault(ref_name, make_schema_definition)
                    ^^^^^^^^^^^^^^^^^^^^^^^^^^^^^^^^^^^^^^^^^^^^^^^^^^^^^^^^
  File "/usr/local/lib/python3.11/site-packages/drf_yasg/openapi.py", line 688, in setdefault
    ret = maker()
          ^^^^^^^
  File "/usr/local/lib/python3.11/site-packages/drf_yasg/inspectors/field.py", line 98, in make_schema_definition
    for property_name, child in serializer.fields.items():
                                ^^^^^^^^^^^^^^^^^
  File "/usr/local/lib/python3.11/site-packages/django_restql/mixins.py", line 424, in fields
    return self.allowed_fields
           ^^^^^^^^^^^^^^^^^^^
  File "/usr/local/lib/python3.11/site-packages/django/utils/functional.py", line 48, in __get__
    res = instance.__dict__[self.name] = self.func(instance)
                                         ^^^^^^^^^^^^^^^^^^^
  File "/usr/local/lib/python3.11/site-packages/django_restql/mixins.py", line 153, in allowed_fields
    fields = super().fields
             ^^^^^^^^^^^^^^
  File "/usr/local/lib/python3.11/site-packages/django/utils/functional.py", line 48, in __get__
    res = instance.__dict__[self.name] = self.func(instance)
                                         ^^^^^^^^^^^^^^^^^^^
  File "/usr/local/lib/python3.11/site-packages/rest_framework/serializers.py", line 356, in fields
    for key, value in self.get_fields().items():
                      ^^^^^^^^^^^^^^^^^
  File "/usr/local/lib/python3.11/site-packages/rest_framework/serializers.py", line 1052, in get_fields
    field_names = self.get_field_names(declared_fields, info)
                  ^^^^^^^^^^^^^^^^^^^^^^^^^^^^^^^^^^^^^^^^^^^
  File "/usr/local/lib/python3.11/site-packages/rest_framework/serializers.py", line 1175, in get_field_names
    assert field_name in fields, (
           ^^^^^^^^^^^^^^^^^^^^
AssertionError: The field '' was included on serializer VipSerializer in the 'exclude' option, but does not match any model field.
Traceback (most recent call last):
  File "/usr/local/lib/python3.11/site-packages/rest_framework/views.py", line 506, in dispatch
    response = handler(request, *args, **kwargs)
               ^^^^^^^^^^^^^^^^^^^^^^^^^^^^^^^^^
  File "/usr/local/lib/python3.11/site-packages/drf_yasg/views.py", line 94, in get
    schema = generator.get_schema(request, self.public)
             ^^^^^^^^^^^^^^^^^^^^^^^^^^^^^^^^^^^^^^^^^^
  File "/Users/mac/Desktop/work/server/apps/utils/swagger.py", line 39, in get_schema
    swagger = super().get_schema(request, public)
              ^^^^^^^^^^^^^^^^^^^^^^^^^^^^^^^^^^^
  File "/usr/local/lib/python3.11/site-packages/drf_yasg/generators.py", line 248, in get_schema
    paths, prefix = self.get_paths(endpoints, components, request, public)
                    ^^^^^^^^^^^^^^^^^^^^^^^^^^^^^^^^^^^^^^^^^^^^^^^^^^^^^^
  File "/usr/local/lib/python3.11/site-packages/drf_yasg/generators.py", line 406, in get_paths
    operation = self.get_operation(view, path, prefix, method, components, request)
                ^^^^^^^^^^^^^^^^^^^^^^^^^^^^^^^^^^^^^^^^^^^^^^^^^^^^^^^^^^^^^^^^^^^
  File "/usr/local/lib/python3.11/site-packages/drf_yasg/generators.py", line 448, in get_operation
    operation = view_inspector.get_operation(operation_keys)
                ^^^^^^^^^^^^^^^^^^^^^^^^^^^^^^^^^^^^^^^^^^^^
  File "/usr/local/lib/python3.11/site-packages/drf_yasg/inspectors/view.py", line 45, in get_operation
    responses = self.get_responses()
                ^^^^^^^^^^^^^^^^^^^^
  File "/usr/local/lib/python3.11/site-packages/drf_yasg/inspectors/view.py", line 180, in get_responses
    response_serializers = self.get_response_serializers()
                           ^^^^^^^^^^^^^^^^^^^^^^^^^^^^^^^
  File "/usr/local/lib/python3.11/site-packages/drf_yasg/inspectors/view.py", line 235, in get_response_serializers
    responses = self.get_default_responses()
                ^^^^^^^^^^^^^^^^^^^^^^^^^^^^
  File "/usr/local/lib/python3.11/site-packages/drf_yasg/inspectors/view.py", line 211, in get_default_responses
    default_schema = self.serializer_to_schema(default_schema) or ''
                     ^^^^^^^^^^^^^^^^^^^^^^^^^^^^^^^^^^^^^^^^^
  File "/usr/local/lib/python3.11/site-packages/drf_yasg/inspectors/base.py", line 438, in serializer_to_schema
    return self.probe_inspectors(
           ^^^^^^^^^^^^^^^^^^^^^^
  File "/usr/local/lib/python3.11/site-packages/drf_yasg/inspectors/base.py", line 110, in probe_inspectors
    result = method(obj, **kwargs)
             ^^^^^^^^^^^^^^^^^^^^^
  File "/usr/local/lib/python3.11/site-packages/drf_yasg/inspectors/field.py", line 38, in get_schema
    return self.probe_field_inspectors(serializer, openapi.Schema, self.use_definitions)
           ^^^^^^^^^^^^^^^^^^^^^^^^^^^^^^^^^^^^^^^^^^^^^^^^^^^^^^^^^^^^^^^^^^^^^^^^^^^^^
  File "/usr/local/lib/python3.11/site-packages/drf_yasg/inspectors/base.py", line 228, in probe_field_inspectors
    return self.probe_inspectors(
           ^^^^^^^^^^^^^^^^^^^^^^
  File "/usr/local/lib/python3.11/site-packages/drf_yasg/inspectors/base.py", line 110, in probe_inspectors
    result = method(obj, **kwargs)
             ^^^^^^^^^^^^^^^^^^^^^
  File "/usr/local/lib/python3.11/site-packages/drf_yasg/inspectors/field.py", line 129, in field_to_swagger_object
    actual_schema = definitions.setdefault(ref_name, make_schema_definition)
                    ^^^^^^^^^^^^^^^^^^^^^^^^^^^^^^^^^^^^^^^^^^^^^^^^^^^^^^^^
  File "/usr/local/lib/python3.11/site-packages/drf_yasg/openapi.py", line 688, in setdefault
    ret = maker()
          ^^^^^^^
  File "/usr/local/lib/python3.11/site-packages/drf_yasg/inspectors/field.py", line 98, in make_schema_definition
    for property_name, child in serializer.fields.items():
                                ^^^^^^^^^^^^^^^^^
  File "/usr/local/lib/python3.11/site-packages/django_restql/mixins.py", line 424, in fields
    return self.allowed_fields
           ^^^^^^^^^^^^^^^^^^^
  File "/usr/local/lib/python3.11/site-packages/django/utils/functional.py", line 48, in __get__
    res = instance.__dict__[self.name] = self.func(instance)
                                         ^^^^^^^^^^^^^^^^^^^
  File "/usr/local/lib/python3.11/site-packages/django_restql/mixins.py", line 153, in allowed_fields
    fields = super().fields
             ^^^^^^^^^^^^^^
  File "/usr/local/lib/python3.11/site-packages/django/utils/functional.py", line 48, in __get__
    res = instance.__dict__[self.name] = self.func(instance)
                                         ^^^^^^^^^^^^^^^^^^^
  File "/usr/local/lib/python3.11/site-packages/rest_framework/serializers.py", line 356, in fields
    for key, value in self.get_fields().items():
                      ^^^^^^^^^^^^^^^^^
  File "/usr/local/lib/python3.11/site-packages/rest_framework/serializers.py", line 1052, in get_fields
    field_names = self.get_field_names(declared_fields, info)
                  ^^^^^^^^^^^^^^^^^^^^^^^^^^^^^^^^^^^^^^^^^^^
  File "/usr/local/lib/python3.11/site-packages/rest_framework/serializers.py", line 1175, in get_field_names
    assert field_name in fields, (
           ^^^^^^^^^^^^^^^^^^^^
AssertionError: The field '' was included on serializer VipSerializer in the 'exclude' option, but does not match any model field.
